<?xml version="1.0" encoding="UTF-8"?>
<testng-results skipped="0" failed="2" ignored="2" total="5" passed="1">
  <reporter-output>
  </reporter-output>
  <suite name="Suite" duration-ms="51" started-at="2021-05-26T07:02:44 EDT" finished-at="2021-05-26T07:02:44 EDT">
    <groups>
      <group name="acceptance">
        <method signature="GroupingTest3.checkoutTest()[pri:2, instance:groupingTests.GroupingTest3@43814d18]" name="checkoutTest" class="groupingTests.GroupingTest3"/>
        <method signature="GroupingTest3.loginTest()[pri:5, instance:groupingTests.GroupingTest3@43814d18]" name="loginTest" class="groupingTests.GroupingTest3"/>
      </group> <!-- acceptance -->
      <group name="cross browser">
        <method signature="GroupingTest3.checkoutTest()[pri:2, instance:groupingTests.GroupingTest3@43814d18]" name="checkoutTest" class="groupingTests.GroupingTest3"/>
        <method signature="GroupingTest3.loginTest()[pri:5, instance:groupingTests.GroupingTest3@43814d18]" name="loginTest" class="groupingTests.GroupingTest3"/>
        <method signature="GroupingTest3.trackingTest()[pri:1, instance:groupingTests.GroupingTest3@43814d18]" name="trackingTest" class="groupingTests.GroupingTest3"/>
      </group> <!-- cross browser -->
    </groups>
    <test name="Test" duration-ms="51" started-at="2021-05-26T07:02:44 EDT" finished-at="2021-05-26T07:02:44 EDT">
      <class name="groupingTests.GroupingTest3">
        <test-method status="FAIL" signature="trackingTest()[pri:1, instance:groupingTests.GroupingTest3@43814d18]" name="trackingTest" duration-ms="11" started-at="2021-05-26T07:02:44 EDT" finished-at="2021-05-26T07:02:44 EDT">
          <exception class="java.lang.AssertionError">
            <message>
              <![CDATA[expected [9] but found [8]]]>
            </message>
            <full-stacktrace>
              <![CDATA[java.lang.AssertionError: expected [9] but found [8]
at org.testng.Assert.fail(Assert.java:97)
at org.testng.Assert.assertEqualsImpl(Assert.java:136)
at org.testng.Assert.assertEquals(Assert.java:118)
at org.testng.Assert.assertEquals(Assert.java:839)
at org.testng.Assert.assertEquals(Assert.java:849)
at groupingTests.GroupingTest3.trackingTest(GroupingTest3.java:33)
at sun.reflect.NativeMethodAccessorImpl.invoke0(Native Method)
at sun.reflect.NativeMethodAccessorImpl.invoke(NativeMethodAccessorImpl.java:62)
at sun.reflect.DelegatingMethodAccessorImpl.invoke(DelegatingMethodAccessorImpl.java:43)
at java.lang.reflect.Method.invoke(Method.java:498)
at org.testng.internal.MethodInvocationHelper.invokeMethod(MethodInvocationHelper.java:133)
at org.testng.internal.TestInvoker.invokeMethod(TestInvoker.java:584)
at org.testng.internal.TestInvoker.invokeTestMethod(TestInvoker.java:172)
at org.testng.internal.MethodRunner.runInSequence(MethodRunner.java:46)
at org.testng.internal.TestInvoker$MethodInvocationAgent.invoke(TestInvoker.java:804)
at org.testng.internal.TestInvoker.invokeTestMethods(TestInvoker.java:145)
at org.testng.internal.TestMethodWorker.invokeTestMethods(TestMethodWorker.java:146)
at org.testng.internal.TestMethodWorker.run(TestMethodWorker.java:128)
at java.util.ArrayList.forEach(ArrayList.java:1257)
at org.testng.TestRunner.privateRun(TestRunner.java:770)
at org.testng.TestRunner.run(TestRunner.java:591)
at org.testng.SuiteRunner.runTest(SuiteRunner.java:402)
at org.testng.SuiteRunner.runSequentially(SuiteRunner.java:396)
at org.testng.SuiteRunner.privateRun(SuiteRunner.java:355)
at org.testng.SuiteRunner.run(SuiteRunner.java:304)
at org.testng.SuiteRunnerWorker.runSuite(SuiteRunnerWorker.java:53)
at org.testng.SuiteRunnerWorker.run(SuiteRunnerWorker.java:96)
at org.testng.TestNG.runSuitesSequentially(TestNG.java:1180)
at org.testng.TestNG.runSuitesLocally(TestNG.java:1102)
at org.testng.TestNG.runSuites(TestNG.java:1032)
at org.testng.TestNG.run(TestNG.java:1000)
at org.testng.remote.AbstractRemoteTestNG.run(AbstractRemoteTestNG.java:115)
at org.testng.remote.RemoteTestNG.initAndRun(RemoteTestNG.java:251)
at org.testng.remote.RemoteTestNG.main(RemoteTestNG.java:77)
]]>
            </full-stacktrace>
          </exception> <!-- java.lang.AssertionError -->
          <reporter-output>
          </reporter-output>
        </test-method> <!-- trackingTest -->
        <test-method status="FAIL" signature="checkoutTest()[pri:2, instance:groupingTests.GroupingTest3@43814d18]" name="checkoutTest" duration-ms="1" started-at="2021-05-26T07:02:44 EDT" finished-at="2021-05-26T07:02:44 EDT">
          <exception class="java.lang.AssertionError">
            <message>
              <![CDATA[expected [7] but found [5]]]>
            </message>
            <full-stacktrace>
              <![CDATA[java.lang.AssertionError: expected [7] but found [5]
at org.testng.Assert.fail(Assert.java:97)
at org.testng.Assert.assertEqualsImpl(Assert.java:136)
at org.testng.Assert.assertEquals(Assert.java:118)
at org.testng.Assert.assertEquals(Assert.java:839)
at org.testng.Assert.assertEquals(Assert.java:849)
at groupingTests.GroupingTest3.checkoutTest(GroupingTest3.java:27)
at sun.reflect.NativeMethodAccessorImpl.invoke0(Native Method)
at sun.reflect.NativeMethodAccessorImpl.invoke(NativeMethodAccessorImpl.java:62)
at sun.reflect.DelegatingMethodAccessorImpl.invoke(DelegatingMethodAccessorImpl.java:43)
at java.lang.reflect.Method.invoke(Method.java:498)
at org.testng.internal.MethodInvocationHelper.invokeMethod(MethodInvocationHelper.java:133)
at org.testng.internal.TestInvoker.invokeMethod(TestInvoker.java:584)
at org.testng.internal.TestInvoker.invokeTestMethod(TestInvoker.java:172)
at org.testng.internal.MethodRunner.runInSequence(MethodRunner.java:46)
at org.testng.internal.TestInvoker$MethodInvocationAgent.invoke(TestInvoker.java:804)
at org.testng.internal.TestInvoker.invokeTestMethods(TestInvoker.java:145)
at org.testng.internal.TestMethodWorker.invokeTestMethods(TestMethodWorker.java:146)
at org.testng.internal.TestMethodWorker.run(TestMethodWorker.java:128)
at java.util.ArrayList.forEach(ArrayList.java:1257)
at org.testng.TestRunner.privateRun(TestRunner.java:770)
at org.testng.TestRunner.run(TestRunner.java:591)
at org.testng.SuiteRunner.runTest(SuiteRunner.java:402)
at org.testng.SuiteRunner.runSequentially(SuiteRunner.java:396)
at org.testng.SuiteRunner.privateRun(SuiteRunner.java:355)
at org.testng.SuiteRunner.run(SuiteRunner.java:304)
at org.testng.SuiteRunnerWorker.runSuite(SuiteRunnerWorker.java:53)
at org.testng.SuiteRunnerWorker.run(SuiteRunnerWorker.java:96)
at org.testng.TestNG.runSuitesSequentially(TestNG.java:1180)
at org.testng.TestNG.runSuitesLocally(TestNG.java:1102)
at org.testng.TestNG.runSuites(TestNG.java:1032)
at org.testng.TestNG.run(TestNG.java:1000)
at org.testng.remote.AbstractRemoteTestNG.run(AbstractRemoteTestNG.java:115)
at org.testng.remote.RemoteTestNG.initAndRun(RemoteTestNG.java:251)
at org.testng.remote.RemoteTestNG.main(RemoteTestNG.java:77)
]]>
            </full-stacktrace>
          </exception> <!-- java.lang.AssertionError -->
          <reporter-output>
          </reporter-output>
        </test-method> <!-- checkoutTest -->
        <test-method status="PASS" signature="loginTest()[pri:5, instance:groupingTests.GroupingTest3@43814d18]" name="loginTest" duration-ms="1" started-at="2021-05-26T07:02:44 EDT" finished-at="2021-05-26T07:02:44 EDT">
          <reporter-output>
          </reporter-output>
        </test-method> <!-- loginTest -->
      </class> <!-- groupingTests.GroupingTest3 -->
    </test> <!-- Test -->
  </suite> <!-- Suite -->
</testng-results>
